## 211019_TIL

## 학습내용

## Error Handling

굳이 말하지 않아도 에러 처리가 중요하다는 것을 알 것이다. 모든 프로그램이 내가 원하는 것 처럼 잘 작동하지만은 않기 때문에 이에 대비해줘야 한다.

디스크에서 파일을 읽어올 때도, 다양한 오류가 있을 수 있는 것 처럼 swift 내에서 에러를 처리할 때도 각 상황에 따라 맞게 그 원인을 알려주고 관리해주면 좋다. 

주로 에러 처리를 할 때 enum 타입으로 에러를 특정지어준다. 

```swift
enum CustomError: Error {
	case invalidInput
	case outOfStock
	case notEnoughCount
}
```

`Error` 프로토콜은 비어있는데, 이를 채택함으로써 해당 타입은 에러 핸들링을 위해 사용하겠다는 의미를 갖게 된다. 

```swift
extension Error {

    /// Retrieve the localized description for this error.
    public var localizedDescription: String { get }
}
```

Error 타입을 채택하면 에러에 해당하는 문구를 localizedDescription을 통해 받을 수 있다. 

이제 에러가 발생하게 되면 던져주게(`throw`) 되는데, 이는 곧 문제가 있기 때문에 정상적으로 실행이 될 수 없음을 말한다. 이 때 `throw` 키워드를 써서 에러 내용을 전달해 줄 수 있다.

```swift
throw CustomError.invalidInput
```

이제 이렇게 에러가 던져지면, 이를 처리해주는 역할도 있어야 할 것이다. 예를 들어, 문제를 해결하기 위해 대안으로 시도를 해보거나, 사용자에게 실패를 알릴 수 있을 것이다. 

swift에는 에러를 처리하는 4가지 방법이 있다고 한다.
- 에러 전파(propagating)
- `do-catch`문
- 에러를 옵셔널로 처리하기
- 에러가 발생하지 않을 것이라고 우기기(?)

### Propagating
함수, 메서드, 이니셜라이저에서 오류가 발생할 수 있음을 알리기 위해서 함수의 파라미터 뒷 부분에 `throws` 키워드를 붙여 표시할 수 있다. 즉 `throws`가 붙어있는 함수는 오류를 뱉을 수 있는 함수인 것이다. 그리고 함수의 화살표(->) 이전에 사용해야 한다. 

```swift
func canThrowErrors() throws -> String
```

그리고 에러를 던져주는 함수를 사용할 때는 앞에 `try` 키워드를 붙여줘야 한다. 

```swift
func sum(a: Int, b: Int) throws {
    if a > 10 {
        throw CustomError.invalidInput
    }
    
    print(a+b)
}

try sum(a: 5, b: 5) // 10
try sum(a: 100, b: 5) // CustomError.invalidInput
```

그리고 만약 에러가 발생해서 throw 부분이 실행되면 return 처럼 바로 함수가 종료되게 된다. 

### `do-catch`문

`do-catch`은 코드 블럭으로 나누어 에러를 처리할 수 있다. 만약 do 부분에서 에러가 발생해서 던져졌다면 catch 부분에서 알맞는 에러에 매칭되어 에러를 처리할 수 있게 해준다. 

일반적으로 다음과 같이 작성한다. 

```swift
do {
    try expression
    statements
} catch pattern 1 {
    statements
} catch pattern 2 where condition {
    statements
} catch pattern 3, pattern 4 where condition {
    statements
} catch {
    statements
}
```

만약 catch 부분에서 충족되는 에러 패턴이 없다면 `error`라는 지역상수에 매칭되어 에러를 처리하게 된다. 

```swift
func sum(a: Int, b: Int) throws -> Int {
    if a > 10 {
        throw CustomError.invalidInput
    }
    
   
    let operated = a + b
    
    if operated < 100 {
        throw CustomError.notEnough
    }
    return operated
}

do {
    let result = try sum(a: 5, b: 20)
    print("합은 \(result)")
} catch CustomError.invalidInput {
    print("입력부터 잘못되었음!")
} catch CustomError.notEnough {
    print("합이 너무 낮음")
} catch {
    print("예상하지 못한 에러: \(error)")
}

// 합이 너무 낮음
```

위의 catch에 모든 케이스가 없을 경우, 예상하지 못한 error를 출력해주게 된다. 

### 에러를 옵셔널로 처리하기 

`try?` 키워드를 사용하면 에러를 옵셔널 값처럼 다룰 수 있다. 만약 에러가 나오면 nil이 되고, 정상적으로 실행된다면 원하는 방식대로 잘 흘러가게 되는 것이다. 

```swift
let resultNil = try? sum(a: 10, b: 5) // nil
let result = try? sum(a: 5, b: 100) // 105
```

당연히 옵셔널이니 옵셔널 바인딩, 체이닝 모두 가능하게 된다! 

### 에러 전파를 불가하게 하는 방법

옵셔널 강제 언래핑과 유사한 방법이다. `try!` 키워드를 사용하는데, 함수가 throws 키워드를 가지고 있음에도, 절대 에러를 반환하지 않을거라고 판단하는 경우에 사용 가능하다. 

```swift
let resultNil = try! sum(a: 10, b: 5)
```

이렇게 하면 프로그램이 죽어버린다. 에러가 발생했는데   강제 언래핑처럼 느낌표(!)를 사용했기 때문이다. 

```swift
let result = try! sum(a: 5, b: 100) // 105
```

에러가 발생하지 않는 경우는 원래 의도한 대로 잘 나오게 된다. 

#### + defer

defer는 해당 코드 블록을 벗어나기 직전에 무조건 호출되는 기능을 갖고 있다. 

```swift
for i in 0..<10 {
    defer {
        print("\(i)바퀴째")
    }
    
    print(i)
}
// 0
// 0바퀴째
// 1
// 1바퀴째
// 2
// 2바퀴째
// 3
// 3바퀴째
// 4
// 4바퀴째
// 5
// 5바퀴째
// 6
// 6바퀴째
// 7
// 7바퀴째
// 8
// 8바퀴째
// 9
// 9바퀴째
```
보다싶이 defer는 마지막에 실행되는 것을 볼 수 있다. 

그럼 defer가 중첩되는 경우는 어떨까? 

```swift
for i in 0..<3 {
    defer {
        defer {
            print("하이")
        }
        print("\(i)바퀴째")
    }
    
    print(i)
}
// 0
// 0바퀴째
// 하이
// 1
// 1바퀴째
// 하이
// 2
// 2바퀴째
// 하이
```

우선 같은 코드 블럭 기준으로, defer 밖의 코드가 먼저 실행이 되고, 바깥의 defer 먼저 실행이 된다. 그 다음 안에 있는 defer가 실행이 된다. 즉 defer의 바깥 코드블록 부터 실행이 되는 것이다. 

### localizedError 프로토콜

특정 에러가 발생했을 때 localized 메세지를 제공해주는 역할은 한다.

소스를 보면 아래와 같이 구성되어있다. 

```swift
public protocol LocalizedError : Error {

    /// A localized message describing what error occurred.
    var errorDescription: String? { get }

    /// A localized message describing the reason for the failure.
    var failureReason: String? { get }

    /// A localized message describing how one might recover from the failure.
    var recoverySuggestion: String? { get }

    /// A localized message providing "help" text if the user requests help.
    var helpAnchor: String? { get }
}
```
- errorDescription : 어떤 에러가 발생했는지?
- failureReason : 어떤 이유에서 실패했는지?
- recoverySuggestion : 어떻게 실패를 극복할 수 있는지 
- helpAnchor : 사용자가 도움을 요청하면 도움을 준다. 



## Dictionary initialization

딕셔너리의 이니셜라이저를 활용하여 생성, 초기화하는데 주로 쓰이는 방법이 두 가지가 있다. 

### `init(uniqueKeysWithValues)`

키 배열과 값 배열을 묶어서 전달해주면 딕셔너리로 만들어준다. 

```swift
let keys = ["a","b","c"]
let values = [1,2,3]

let dict = Dictionary(uniqueKeysWithValues: zip(keys,values))
// ["a": 1, "b": 2, "c": 3]
```

### `init(_:uniquingKeysWith:)`

```swift
let keys = ["a","b","c","a","b","a"]

let dict = Dictionary(keys.map { ($0,1) }, uniquingKeysWith: { (first,_) in first })
// ["a": 1, "b": 1, "c": 1]
```

처음 나온 키/값을 딕셔너리에 고정하고 싶다면 `(first, _) in first` 를 마지막에 등장한 키/값을 기준으로 딕셔너리를 만들고 싶다면 `(_, last) in last`를 적어주면 된다.

```swift
let keys = ["a","b","c","a","b","a"]

let dict = Dictionary(keys.map { ($0,1) }, uniquingKeysWith: +)
// ["a": 3, "b": 2, "c": 1]
```

이렇게 `+`를 적어주는 경우 키에 대한 값이 누적으로 쌓이게 된다. 

---

**Ref**
[Error Handling](https://docs.swift.org/swift-book/LanguageGuide/ErrorHandling.html)
[Dictionary init](https://developer.apple.com/documentation/swift/dictionary/3127161-init)

